{"name": "测试数据：【 test003，123456，False，200，账号不存在，请重新输入或联系管理员！】", "status": "broken", "statusDetails": {"message": "AttributeError: 'ResultBase' object has no attribute 'error'", "trace": "self = <testcases.api_test.test_03_login.TestUserLogin object at 0x04774DF0>\nusername = 'test003', password = '123456', except_result = False\nexcept_code = 200, except_msg = '账号不存在，请重新输入或联系管理员！'\n\n    @allure.story(\"用例--登录用户\")\n    @allure.description(\"该用例是针对获取用户登录接口的测试\")\n    @allure.issue(\"http://10.5.15.116/#/home\", name=\"点击，跳转到对应BUG的链接地址\")\n    @allure.testcase(\"暂无\", name=\"点击，跳转到对应用例的链接地址\")\n    @allure.title(\"测试数据：【 {username}，{password}，{except_result}，{except_code}，{except_msg}】\")\n    @pytest.mark.single\n    @pytest.mark.parametrize(\"username, password, except_result, except_code, except_msg\",\n                             api_data[\"test_login_user\"])\n    def test_login_user(self, username, password, except_result, except_code, except_msg):\n        logger.info(\"*************** 开始执行用例 ***************\")\n        result = login_user(username, password)\n        step_1(username)\n>       assert result.success == except_result, result.error\nE       AttributeError: 'ResultBase' object has no attribute 'error'\n\ntest_03_login.py:30: AttributeError"}, "description": "该用例是针对获取用户登录接口的测试", "steps": [{"name": "步骤1 ==>> 登录用户", "status": "passed", "parameters": [{"name": "username", "value": "'test003'"}], "start": 1622555217924, "stop": 1622555217924}], "attachments": [{"name": "log", "source": "9f9c98cd-d5bb-4cba-a773-cead807d11e6-attachment.txt", "type": "text/plain"}, {"name": "stdout", "source": "4ad99ade-f767-4c45-b527-51404ebfb805-attachment.txt", "type": "text/plain"}, {"name": "stderr", "source": "9589fe88-f0da-4349-92eb-8c2459eb687f-attachment.txt", "type": "text/plain"}], "parameters": [{"name": "username", "value": "'test003'"}, {"name": "password", "value": "'123456'"}, {"name": "except_result", "value": "False"}, {"name": "except_code", "value": "200"}, {"name": "except_msg", "value": "'账号不存在，请重新输入或联系管理员！'"}], "start": 1622555217889, "stop": 1622555217925, "uuid": "8ef9d0f7-4a9a-45a8-b952-c495a6ed3425", "historyId": "f2a655d3b4d5107baf247f9d10b1833c", "testCaseId": "7272db244dabef390096479ae3196642", "fullName": "testcases.api_test.test_03_login.TestUserLogin#test_login_user", "labels": [{"name": "feature", "value": "用户登录模块"}, {"name": "epic", "value": "针对单个接口的测试"}, {"name": "severity", "value": "normal"}, {"name": "story", "value": "用例--登录用户"}, {"name": "tag", "value": "single"}, {"name": "parentSuite", "value": "testcases.api_test"}, {"name": "suite", "value": "test_03_login"}, {"name": "subSuite", "value": "TestUserLogin"}, {"name": "host", "value": "LAPTOP-1UC29CD2"}, {"name": "thread", "value": "2296-MainThread"}, {"name": "framework", "value": "pytest"}, {"name": "language", "value": "cpython3"}, {"name": "package", "value": "testcases.api_test.test_03_login"}], "links": [{"type": "test_case", "url": "暂无", "name": "点击，跳转到对应用例的链接地址"}, {"type": "issue", "url": "http://10.5.15.116/#/home", "name": "点击，跳转到对应BUG的链接地址"}]}