{"name": "测试数据：【 test003，False，200，账号不存在，请重新输入或联系管理员！】", "status": "broken", "statusDetails": {"message": "AttributeError: 'ResultBase' object has no attribute 'error'", "trace": "self = <testcases.api_test.test_03_login.TestUserLogin object at 0x04B02DF0>, username = 'test003', except_result = False, except_code = 200, except_msg = '账号不存在，请重新输入或联系管理员！'\n\n    @allure.story(\"用例--检查登录用户\")\n    @allure.description(\"该用例是针对获取用户登录接口的测试\")\n    @allure.issue(\"http://10.5.15.116/#/home\", name=\"点击，跳转到对应BUG的链接地址\")\n    @allure.testcase(\"暂无\", name=\"点击，跳转到对应用例的链接地址\")\n    @allure.title(\"测试数据：【 {username}，{except_result}，{except_code}，{except_msg}】\")\n    @pytest.mark.single\n    @pytest.mark.parametrize(\"username, except_result, except_code, except_msg\",\n                             api_data[\"test_check_user\"])\n    def test_check_user(self, username, except_result, except_code, except_msg):\n        logger.info(\"*************** 开始执行用例 ***************\")\n        result = check_user(username)\n        step_1(username)\n>       assert result.success == except_result, result.error\nE       AttributeError: 'ResultBase' object has no attribute 'error'\n\ntestcases\\api_test\\test_03_login.py:52: AttributeError"}, "description": "该用例是针对获取用户登录接口的测试", "steps": [{"name": "步骤1 ==>> 登录用户", "status": "passed", "parameters": [{"name": "username", "value": "'test003'"}], "start": 1622569288010, "stop": 1622569288010}], "attachments": [{"name": "log", "source": "c040d224-e946-48ef-91a5-7fe2e0350da2-attachment.txt", "type": "text/plain"}, {"name": "stderr", "source": "3a515994-f52d-404f-b2f3-674c08a2ef8d-attachment.txt", "type": "text/plain"}], "parameters": [{"name": "username", "value": "'test003'"}, {"name": "except_result", "value": "False"}, {"name": "except_code", "value": "200"}, {"name": "except_msg", "value": "'账号不存在，请重新输入或联系管理员！'"}], "start": 1622569287997, "stop": 1622569288012, "uuid": "0ce2f191-3eb5-4ed7-896b-e75b5531cd18", "historyId": "38b7ba371414e38be2a72df266f3c7e7", "testCaseId": "4965f76335de5c80d0580a0c1fbc27f9", "fullName": "testcases.api_test.test_03_login.TestUserLogin#test_check_user", "labels": [{"name": "story", "value": "用例--检查登录用户"}, {"name": "epic", "value": "针对单个接口的测试"}, {"name": "feature", "value": "用户登录模块"}, {"name": "severity", "value": "normal"}, {"name": "tag", "value": "single"}, {"name": "parentSuite", "value": "testcases.api_test"}, {"name": "suite", "value": "test_03_login"}, {"name": "subSuite", "value": "TestUserLogin"}, {"name": "host", "value": "LAPTOP-1UC29CD2"}, {"name": "thread", "value": "5824-MainThread"}, {"name": "framework", "value": "pytest"}, {"name": "language", "value": "cpython3"}, {"name": "package", "value": "testcases.api_test.test_03_login"}], "links": [{"type": "test_case", "url": "暂无", "name": "点击，跳转到对应用例的链接地址"}, {"type": "issue", "url": "http://10.5.15.116/#/home", "name": "点击，跳转到对应BUG的链接地址"}]}