{"name": "测试数据：【 test003，123456，False，200，账号不存在，请重新输入或联系管理员！】", "status": "broken", "statusDetails": {"message": "AttributeError: 'ResultBase' object has no attribute 'error'", "trace": "self = <testcases.api_test.test_03_login.TestUserLogin object at 0x04F62E30>, username = 'test003', password = '123456', except_result = False, except_code = 200, except_msg = '账号不存在，请重新输入或联系管理员！'\n\n    @allure.story(\"用例--登录用户\")\n    @allure.description(\"该用例是针对获取用户登录接口的测试\")\n    @allure.issue(\"http://10.5.15.116/#/home\", name=\"点击，跳转到对应BUG的链接地址\")\n    @allure.testcase(\"暂无\", name=\"点击，跳转到对应用例的链接地址\")\n    @allure.title(\"测试数据：【 {username}，{password}，{except_result}，{except_code}，{except_msg}】\")\n    @pytest.mark.single\n    @pytest.mark.parametrize(\"username, password, except_result, except_code, except_msg\",\n                             api_data[\"test_login_user\"])\n    def test_login_user(self, username, password, except_result, except_code, except_msg):\n        logger.info(\"*************** 开始执行用例 ***************\")\n        result = login_user(username, password)\n        step_1(username)\n>       assert result.success == except_result, result.error\nE       AttributeError: 'ResultBase' object has no attribute 'error'\n\ntestcases\\api_test\\test_03_login.py:30: AttributeError"}, "description": "该用例是针对获取用户登录接口的测试", "steps": [{"name": "步骤1 ==>> 登录用户", "status": "passed", "parameters": [{"name": "username", "value": "'test003'"}], "start": 1622569998611, "stop": 1622569998611}], "attachments": [{"name": "log", "source": "8ec54705-4e52-47e8-a923-60163afc2161-attachment.txt", "type": "text/plain"}, {"name": "stdout", "source": "c90d97dc-0219-470d-af7a-f626014f12ff-attachment.txt", "type": "text/plain"}, {"name": "stderr", "source": "9dc25977-3540-40e5-b750-1c94035d662c-attachment.txt", "type": "text/plain"}], "parameters": [{"name": "username", "value": "'test003'"}, {"name": "password", "value": "'123456'"}, {"name": "except_result", "value": "False"}, {"name": "except_code", "value": "200"}, {"name": "except_msg", "value": "'账号不存在，请重新输入或联系管理员！'"}], "start": 1622569998571, "stop": 1622569998612, "uuid": "efd55a84-912c-44ef-a1d9-0da662b80ca1", "historyId": "f2a655d3b4d5107baf247f9d10b1833c", "testCaseId": "7272db244dabef390096479ae3196642", "fullName": "testcases.api_test.test_03_login.TestUserLogin#test_login_user", "labels": [{"name": "feature", "value": "用户登录模块"}, {"name": "severity", "value": "normal"}, {"name": "story", "value": "用例--登录用户"}, {"name": "epic", "value": "针对单个接口的测试"}, {"name": "tag", "value": "single"}, {"name": "parentSuite", "value": "testcases.api_test"}, {"name": "suite", "value": "test_03_login"}, {"name": "subSuite", "value": "TestUserLogin"}, {"name": "host", "value": "LAPTOP-1UC29CD2"}, {"name": "thread", "value": "18320-MainThread"}, {"name": "framework", "value": "pytest"}, {"name": "language", "value": "cpython3"}, {"name": "package", "value": "testcases.api_test.test_03_login"}], "links": [{"type": "test_case", "url": "暂无", "name": "点击，跳转到对应用例的链接地址"}, {"type": "issue", "url": "http://10.5.15.116/#/home", "name": "点击，跳转到对应BUG的链接地址"}]}